<?xml version="1.0" encoding="utf-8"?>
<!-- This URDF was automatically created by SolidWorks to URDF Exporter! Originally created by Stephen Brawner (brawner@gmail.com) 
     Commit Version: 1.5.1-0-g916b5db  Build Version: 1.5.7152.31018
     For more information, please see http://wiki.ros.org/sw_urdf_exporter -->
<robot
  name="jaka5">
    <!-- LINK -->
  <!-- <link name="world" /> -->
<link name="dummy"> 
</link>

    <xacro:property name="d455_cam_width" value="0.124"/>
    <xacro:property name="d455_cam_height" value="0.029"/>
    <xacro:property name="d455_cam_depth" value="0.026"/>
    <xacro:property name="d455_cam_mount_from_center_offset" value="0.0158"/>
    <!-- glass cover is 0.1 mm inwards from front aluminium plate -->
    <xacro:property name="d455_glass_to_front" value="0.1e-3"/>
    <!-- see datasheet Revision 009, Fig. 4-4 page 68 -->
    <xacro:property name="d455_zero_depth_to_glass" value="4.55e-3"/>
    <!-- convenience precomputation to avoid clutter-->
    <xacro:property name="d455_mesh_x_offset" value="${d455_cam_mount_from_center_offset-d455_glass_to_front-d455_zero_depth_to_glass}"/>
    <xacro:property name="d455_cam_depth_px" value="${d455_cam_mount_from_center_offset}"/>
    <xacro:property name="d455_cam_depth_py" value="0.0475"/>
    <xacro:property name="d455_cam_depth_pz" value="${d455_cam_height/2}"/>

  <link name="camera_link">
  <visual>
    <origin xyz="0 0 0" rpy="0 0 0"/>
      <geometry>
        <mesh
          filename="package://realsense2_description/meshes/d455.stl" scale="0.001 0.001 0.001"/>
      </geometry>
      <material
        name="">
        <color
          rgba="1 1 1 1" />
      </material>
  </visual>
  <origin xyz="0 0 0" rpy="0 0 0" />
  <!-- 定义相机链接的惯性属性 -->
  <!-- ... -->
</link>

<joint name="camera_joint" type="fixed">
  <origin xyz="0.0475543 0.0273704 -0.0319399" rpy="-3.1235604 0.04989 -0.762024" />
  <parent link="Link_6" />
  <child link="camera_link" />
</joint>

  <link
    name="Link_0">
    <inertial>
      <origin
        xyz="0.00096513 -2.0436E-07 0.019553"
        rpy="0 0 0" />
      <mass
        value="0.51461" />
      <inertia
        ixx="0.00062136"
        ixy="3.6749E-09"
        ixz="3.217E-06"
        iyy="0.00086645"
        iyz="-6.8254E-11"
        izz="0.0013529" />
    </inertial>
    <visual>
      <origin
        xyz="0 0 0"
        rpy="0 0 0" />
      <geometry>
        <mesh
          filename="package://jaka5/meshes/Link_0.STL" />
      </geometry>
      <material
        name="">
        <color
          rgba="1 1 1 1" />
      </material>
    </visual>
    <collision>
      <origin
        xyz="0 0 0"
        rpy="0 0 0" />
      <geometry>
        <mesh
          filename="package://jaka5/meshes/Link_0.STL" />
      </geometry>
    </collision>
  </link>
  
  <joint name="dummy_joint" type="fixed">
     <parent link="dummy"/>
     <child link="Link_0"/>
</joint>
  
<!--   
    <joint name="worlddummy_joint" type="fixed">
     <parent link="world"/>
     <child link="dummy"/>
</joint> -->
  
  
  
  
  
  
  <!--link
    name="Link_0">
    <inertial>
      <origin
        xyz="0.00096513 -2.0436E-07 0.019553"
        rpy="0 0 0" />
      <mass
        value="0.51461" />
      <inertia
        ixx="0.00062136"
        ixy="3.6749E-09"
        ixz="3.217E-06"
        iyy="0.00086645"
        iyz="-6.8254E-11"
        izz="0.0013529" />
    </inertial>
    <visual>
      <origin
        xyz="0 0 0"
        rpy="0 0 0" />
      <geometry>
        <mesh
          filename="package://jaka5/meshes/Link_0.STL" />
      </geometry>
      <material
        name="">
        <color
          rgba="1 1 1 1" />
      </material>
    </visual>
    <collision>
      <origin
        xyz="0 0 0"
        rpy="0 0 0" />
      <geometry>
        <mesh
          filename="package://jaka5/meshes/Link_0.STL" />
      </geometry>
    </collision>
  </link/-->
  <link
    name="Link_1">
    <inertial>
      <origin
        xyz="-9.95605124254965E-07 0.00332172375841702 -0.00151307453678093"
        rpy="0 0 0" />
      <mass
        value="1.92814665834042" />
      <inertia
        ixx="0.00564332197967496"
        ixy="-2.06406149514884E-08"
        ixz="-1.29468636330218E-08"
        iyy="0.00548947482538077"
        iyz="1.93161087253138E-06"
        izz="0.00388876051174396" />
    </inertial>
    <visual>
      <origin
        xyz="0 0 0"
        rpy="0 0 0" />
      <geometry>
        <mesh
          filename="package://jaka5/meshes/Link_1.STL" />
      </geometry>
      <material
        name="">
        <color
          rgba="1 1 1 1" />
      </material>
    </visual>
    <collision>
      <origin
        xyz="0 0 0"
        rpy="0 0 0" />
      <geometry>
        <mesh
          filename="package://jaka5/meshes/Link_1.STL" />
      </geometry>
    </collision>
  </link>
  <joint
    name="joint_1"
    type="revolute">
    <origin
      xyz="0 0 0.12015"
      rpy="0 0 0" />
    <parent
      link="Link_0" />
    <child
      link="Link_1" />
    <axis
      xyz="0 0 1" />
    <limit
      lower="-6.28"
      upper="6.28"
      effort="2000"
      velocity="1.57" />
  </joint>
  <link
    name="Link_2">
    <inertial>
      <origin
        xyz="0.215002166333282 1.04794697147748E-06 0.143144093112074"
        rpy="0 0 0" />
      <mass
        value="5.84034185465523" />
      <inertia
        ixx="0.0132170283219531"
        ixy="4.23692985779665E-08"
        ixz="-3.22538927916113E-08"
        iyy="0.0305876243898544"
        iyz="4.77031446643335E-08"
        izz="0.0270803638662797" />
    </inertial>
    <visual>
      <origin
        xyz="0 0 0"
        rpy="0 0 0" />
      <geometry>
        <mesh
          filename="package://jaka5/meshes/Link_2.STL" />
      </geometry>
      <material
        name="">
        <color
          rgba="1 1 1 1" />
      </material>
    </visual>
    <collision>
      <origin
        xyz="0 0 0"
        rpy="0 0 0" />
      <geometry>
        <mesh
          filename="package://jaka5/meshes/Link_2.STL" />
      </geometry>
    </collision>
  </link>
  <joint
    name="joint_2"
    type="revolute">
    <origin
      xyz="0 0 0"
      rpy="-1.5708 0 0" />
    <parent
      link="Link_1" />
    <child
      link="Link_2" />
    <axis
      xyz="0 0 -1" />
    <limit
      lower="-1.48"
      upper="4.62"
      effort="5000"
      velocity="1.57" />
  </joint>
  <link
    name="Link_3">
    <inertial>
      <origin
        xyz="0.190892747309216 1.3764908225411E-05 0.0105861748728921"
        rpy="0 0 0" />
      <mass
        value="2.30172821282921" />
      <inertia
        ixx="0.00252247904913201"
        ixy="1.24150218629087E-07"
        ixz="0.00207396271926679"
        iyy="0.021482434480462"
        iyz="-6.836461457843E-09"
        izz="0.0210560028542014" />
    </inertial>
    <visual>
      <origin
        xyz="0 0 0"
        rpy="0 0 0" />
      <geometry>
        <mesh
          filename="package://jaka5/meshes/Link_3.STL" />
      </geometry>
      <material
        name="">
        <color
          rgba="1 1 1 1" />
      </material>
    </visual>
    <collision>
      <origin
        xyz="0 0 0"
        rpy="0 0 0" />
      <geometry>
        <mesh
          filename="package://jaka5/meshes/Link_3.STL" />
      </geometry>
    </collision>
  </link>
  <joint
    name="joint_3"
    type="revolute">
    <origin
      xyz="0.43 0 0"
      rpy="0 0 0" />
    <parent
      link="Link_2" />
    <child
      link="Link_3" />
    <axis
      xyz="0 0 -1" />
    <limit
      lower="-3.05"
      upper="3.05"
      effort="5000"
      velocity="1.57" />
  </joint>
  <link
    name="Link_4">
    <inertial>
      <origin
        xyz="-2.02258500947572E-07 -0.00580030239181618 0.00267203650826855"
        rpy="0 0 0" />
      <mass
        value="0.707387961473478" />
      <inertia
        ixx="0.000903595051490559"
        ixy="1.15428669682958E-09"
        ixz="1.05671594857086E-08"
        iyy="0.000659704920449867"
        iyz="-5.07453758965962E-05"
        izz="0.000872922137731723" />
    </inertial>
    <visual>
      <origin
        xyz="0 0 0"
        rpy="0 0 0" />
      <geometry>
        <mesh
          filename="package://jaka5/meshes/Link_4.STL" />
      </geometry>
      <material
        name="">
        <color
          rgba="1 1 1 1" />
      </material>
    </visual>
    <collision>
      <origin
        xyz="0 0 0"
        rpy="0 0 0" />
      <geometry>
        <mesh
          filename="package://jaka5/meshes/Link_4.STL" />
      </geometry>
    </collision>
  </link>
  <joint
    name="joint_4"
    type="revolute">
    <origin
      xyz="0.3685 1.185E-05 0.114"
      rpy="-3.1416 0 0" />
    <parent
      link="Link_3" />
    <child
      link="Link_4" />
    <axis
      xyz="0 0 1" />
    <limit
      lower="-1.48"
      upper="4.62"
      effort="2000"
      velocity="1.57" />
  </joint>
  <link
    name="Link_5">
    <inertial>
      <origin
        xyz="1.88609744267154E-07 0.00288901475701922 0.0023423430547238"
        rpy="0 0 0" />
      <mass
        value="0.806925952144721" />
      <inertia
        ixx="0.00164590227416177"
        ixy="-7.61723506124408E-10"
        ixz="2.2727609530509E-08"
        iyy="0.000744711390298614"
        iyz="5.47704328908412E-06"
        izz="0.0016085998891594" />
    </inertial>
    <visual>
      <origin
        xyz="0 0 0"
        rpy="0 0 0" />
      <geometry>
        <mesh
          filename="package://jaka5/meshes/Link_5.STL" />
      </geometry>
      <material
        name="">
        <color
          rgba="1 1 1 1" />
      </material>
    </visual>
    <collision>
      <origin
        xyz="0 0 0"
        rpy="0 0 0" />
      <geometry>
        <mesh
          filename="package://jaka5/meshes/Link_5.STL" />
      </geometry>
    </collision>
  </link>
  <joint
    name="joint_5"
    type="revolute">
    <origin
      xyz="0 -0.1135 0"
      rpy="-1.5708 0 0" />
    <parent
      link="Link_4" />
    <child
      link="Link_5" />
    <axis
      xyz="0 0 -1" />
    <limit
      lower="-6.28"
      upper="6.28"
      effort="3000"
      velocity="1.57" />
  </joint>
  <link
    name="Link_6">
    <inertial>
      <origin
        xyz="2.76225814479503E-05 1.35622550426814E-05 0.0202451138695624"
        rpy="0 0 0" />
      <mass
        value="0.180494479520411" />
      <inertia
        ixx="9.09171999754487E-05"
        ixy="8.73769947524719E-08"
        ixz="8.11300618907862E-08"
        iyy="9.21804791834808E-05"
        iyz="2.02421340977685E-07"
        izz="0.000143814480124944" />
    </inertial>
    <visual>
      <origin
        xyz="0 0 0"
        rpy="0 0 0" />
      <geometry>
        <mesh
          filename="package://jaka5/meshes/Link_6.STL" />
      </geometry>
      <material
        name="">
        <color
          rgba="1 1 1 1" />
      </material>
    </visual>
    <collision>
      <origin
        xyz="0 0 0"
        rpy="0 0 0" />
      <geometry>
        <mesh
          filename="package://jaka5/meshes/Link_6.STL" />
      </geometry>
    </collision>
  </link>
  <joint
    name="joint_6"
    type="revolute">
    <origin
      xyz="0 -0.106 0"
      rpy="-1.5708 0 0" />
    <parent
      link="Link_5" />
    <child
      link="Link_6" />
    <axis
      xyz="0 0 1" />
    <limit
      lower="-6.28"
      upper="6.28"
      effort="1000"
      velocity="1.57" />
  </joint>
</robot>
